Workbook
Name TARIFA_LAND: #REF!
Name TARIFA_OUTBOUND: #REF!
Name TARIFA_SEA: #REF!
Name TOLERANCIA_COSTO: #REF!
Name TOLERANCIA_PCT: #REF!

Sheet Summary
C3: Type | D3: M01 | E3: M19 | F3: M23 | G3: M45 | H3: M46
C4: Sea %PCT | D4: =IFERROR(_xlfn.XLOOKUP(D$3,Sea!$CU$6:$CU$12,Sea!$CY$6:$CY$12,0),0) -> 0.14803945 | E4: =IFERROR(_xlfn.XLOOKUP(E$3,Sea!$CU$6:$CU$12,Sea!$CY$6:$CY$12,0),0) -> 0.49475976 | F4: =IFERROR(_xlfn.XLOOKUP(F$3,Sea!$CU$6:$CU$12,Sea!$CY$6:$CY$12,0),0) -> 0.034281248 | G4: =IFERROR(_xlfn.XLOOKUP(G$3,Sea!$CU$6:$CU$12,Sea!$CY$6:$CY$12,0),0) -> 0.29154587 | H4: =IFERROR(_xlfn.XLOOKUP(H$3,Sea!$CU$6:$CU$12,Sea!$CY$6:$CY$12,0),0) -> 0.031373675
C5: Land %PCT | D5: =IFERROR(_xlfn.XLOOKUP(D$3,land!$CC$3:$CC$10,land!$CE$3:$CE$10,0),0) -> 0 | E5: =IFERROR(_xlfn.XLOOKUP(E$3,land!$CC$3:$CC$10,land!$CE$3:$CE$10,0),0) -> 0.17730461 | F5: =IFERROR(_xlfn.XLOOKUP(F$3,land!$CC$3:$CC$10,land!$CE$3:$CE$10,0),0) -> 0.33799952 | G5: =IFERROR(_xlfn.XLOOKUP(G$3,land!$CC$3:$CC$10,land!$CE$3:$CE$10,0),0) -> 0.05411606 | H5: =IFERROR(_xlfn.XLOOKUP(H$3,land!$CC$3:$CC$10,land!$CE$3:$CE$10,0),0) -> 0.43057981
C6: Outbound %PCT | D6: =IFERROR(_xlfn.XLOOKUP(D$3,Outbound!$BS$9:$BS$14,Outbound!$BU$9:$BU$14,0),0) -> 0.21335361 | E6: =IFERROR(_xlfn.XLOOKUP(E$3,Outbound!$BS$9:$BS$14,Outbound!$BU$9:$BU$14,0),0) -> 0.40998995 | F6: =IFERROR(_xlfn.XLOOKUP(F$3,Outbound!$BS$9:$BS$14,Outbound!$BU$9:$BU$14,0),0) -> 0.031679472 | G6: =IFERROR(_xlfn.XLOOKUP(G$3,Outbound!$BS$9:$BS$14,Outbound!$BU$9:$BU$14,0),0) -> 0.3156942 | H6: =IFERROR(_xlfn.XLOOKUP(H$3,Outbound!$BS$9:$BS$14,Outbound!$BU$9:$BU$14,0),0) -> 0.029282767
B9: Viewer | C9: Arg. Var $ | D9: M01 | E9: M19 | F9: M23 | G9: M45 | H9: M46
B10: Sea | C10: =SUM(D10:H10) -> 135561.06 | D10: =IFERROR(_xlfn.XLOOKUP(D$9,Sea!$CU$6:$CU$12,Sea!$CX$6:$CX$12,0),0) -> 20068.385 | E10: =IFERROR(_xlfn.XLOOKUP(E$9,Sea!$CU$6:$CU$12,Sea!$CX$6:$CX$12,0),0) -> 67070.158 | F10: =IFERROR(_xlfn.XLOOKUP(F$9,Sea!$CU$6:$CU$12,Sea!$CX$6:$CX$12,0),0) -> 4647.2024 | G10: =IFERROR(_xlfn.XLOOKUP(G$9,Sea!$CU$6:$CU$12,Sea!$CX$6:$CX$12,0),0) -> 39522.267 | H10: =IFERROR(_xlfn.XLOOKUP(H$9,Sea!$CU$6:$CU$12,Sea!$CX$6:$CX$12,0),0) -> 4253.0487
B11: Land | C11: =SUM(D11:H11) -> 4339.476 | E11: =IFERROR(_xlfn.XLOOKUP(E$9,land!$CC$3:$CC$10,land!$CD$3:$CD$10,0),0) -> 769.40912 | F11: =IFERROR(_xlfn.XLOOKUP(F$9,land!$CC$3:$CC$10,land!$CD$3:$CD$10,0),0) -> 1466.7408 | G11: =IFERROR(_xlfn.XLOOKUP(G$9,land!$CC$3:$CC$10,land!$CD$3:$CD$10,0),0) -> 234.83535 | H11: =IFERROR(_xlfn.XLOOKUP(H$9,land!$CC$3:$CC$10,land!$CD$3:$CD$10,0),0) -> 1868.4908
B12: Outbound | C12: =SUM(D12:H12) -> 126981.16 | D12: =IFERROR(_xlfn.XLOOKUP(D$9,Outbound!$BS$9:$BS$14,Outbound!$BT$9:$BT$14,0),0) -> 27091.89 | E12: =IFERROR(_xlfn.XLOOKUP(E$9,Outbound!$BS$9:$BS$14,Outbound!$BT$9:$BT$14,0),0) -> 52061.002 | F12: =IFERROR(_xlfn.XLOOKUP(F$9,Outbound!$BS$9:$BS$14,Outbound!$BT$9:$BT$14,0),0) -> 4022.6962 | G12: =IFERROR(_xlfn.XLOOKUP(G$9,Outbound!$BS$9:$BS$14,Outbound!$BT$9:$BT$14,0),0) -> 40087.217 | H12: =IFERROR(_xlfn.XLOOKUP(H$9,Outbound!$BS$9:$BS$14,Outbound!$BT$9:$BT$14,0),0) -> 3718.3599

Sheet Outbound
B1: Data | BC1: Complementari information | BG1: Extraction of transactions | BS1: Output
B3: {=_xlfn.SEQUENCE(1,50)} -> 1 | C3: 2 | D3: 3 | E3: 4 | F3: 5 | G3: 6 | H3: 7 | I3: 8 | J3: 9 | K3: 10 | L3: 11 | M3: 12 | N3: 13 | O3: 14 | P3: 15 | Q3: 16 | R3: 17 | S3: 18 | T3: 19 | U3: 20 | V3: 21 | W3: 22 | X3: 23 | Y3: 24 | Z3: 25 | AA3: 26 | AB3: 27 | AC3: 28 | AD3: 29 | AE3: 30 | AF3: 31 | AG3: 32 | AH3: 33 | AI3: 34 | AJ3: 35 | AK3: 36 | AL3: 37 | AM3: 38 | AN3: 39 | AO3: 40 | AP3: 41 | AQ3: 42 | AR3: 43 | AS3: 44 | AT3: 45 | AU3: 46 | AV3: 47 | AW3: 48 | AX3: 49 | AY3: 50 | BG3: {=_xlfn.TOROW(IF($B$4:$AY$4="x",_xlfn.ANCHORARRAY(B3),1/0),3)} -> 1 | BH3: 2 | BI3: 3 | BJ3: 4 | BK3: 5 | BL3: 13 | BM3: 14 | BN3: 43 | BO3: 44 | BV3: Frida| Martha
B4: X | C4: X | D4: X | E4: X | F4: x | N4: x | O4: x | AR4: x | AS4: x | BG4: {=_xlfn.TOROW(IF($B$4:$AY$4="x",B8:AY8,1/0),3)} -> Inbound/Outbound | BH4: Method | BI4: Reference | BJ4: BU | BK4: Gross Weight | BL4: Customer | BM4: Address | BN4: Item | BO4: Qty Pzas | BV4: Cuanto Fact
BG6: Expand
R7: Pallets | U7: Cartons | X7: Pallets | AA7: Cartons | AD7: Pallets | AG7: Covers | AJ7: Delivery Information | AM7: Invoice Information | AR7: Shipping Information | AU7: SAT Information
B8: Inbound/Outbound | C8: Method | D8: Reference | E8: BU | F8: Gross Weight | G8: Waybill Number | H8: Transport Name | I8: Container Number | J8: On Board | K8: Port Drop Off | L8: Reference | M8: Security Seal | N8: Customer | O8: Address | P8: Company | Q8: Address | R8: Pieces | S8: Net Weight (Kgs) | T8: C. PLT gross weight | U8: Pieces | V8: Net Weight (Kgs) | W8: Gross Weight (Kgs) | X8: Pieces | Y8: Net Weight (Kgs) | Z8: Part. PLT gross weight | AA8: Pieces | AB8: Net Weight (Kgs) | AC8: Gross Weight (Kgs) | AD8: Wood | AE8: Plastic | AF8: No define | AG8: Wood | AH8: Plastic | AI8: No define | AJ8: Number | AK8: Status | AL8: Creation | AM8: OU | AN8: Number | AO8: Creation | AP8: Amount | AQ8: Currency | AR8: Item | AS8: Qty Pzas | AT8: UOM | AU8: Code | AV8: Description | AW8: UOM | AX8: Description | AY8: Fracción Arancelaria | AZ8: Description | BC8: Reference | BD8: Cost (USD) | BE8: Fix Cost | BG8: Inbound/Outbound | BH8: Method | BI8: Reference | BJ8: Customer | BK8: Addres | BL8: BU | BM8: Item | BN8: Qty Pzas | BO8: Gross Weight | BP8: %Proportion | BQ8: Calc_Exp | BS8: BU | BT8: Log. Exp | BU8: %PCT | BV8: Rec. Exp | BW8: Balance | BX8: %Pct Allow
B9: Outbound | C9: Land | D9: {=_xlfn.REGEXEXTRACT(G9,"FG-R-\d{4}LE\d{2}")} -> FG-R-2180LE25 | E9: M23 | F9: {=_xlfn.SWITCH(TRUE,T9>0,T9,Z9)} -> 1098.8 | G9: FG-R-2180LE25.M46-M45-2 | H9: 3 BROTHERS | I9: H06059 | J9: 2026/04/01 00:00:00 | K9: 2026/04/01 00:00:00 | L9: FG-R-2180LE25.M46-M45 | M9: UL-5606471 | N9: JOHNSON ELECTRIC NORTH AMERICA, INC. | O9: (TDS) Transcontinental Distribution Services, Inc 14213 Transportation Ave | P9: Johnson Electric Group Mexico, S. de R. L. de C.V. | Q9: Boulevard Morelos # 1109,Mega Parque Industrial Aeropuerto de Calera,98519, Calera | R9: 5 | S9: 993.8 | T9: 1098.8 | U9: 100 | V9: 870.6 | W9: 993.8 | X9: 0 | Y9: 0 | Z9: 0 | AA9: 0 | AB9: 0 | AC9: 0 | AD9: 0 | AE9: 5 | AF9: 0 | AG9: 0 | AH9: 5 | AI9: 0 | AJ9: 6171311 | AK9: Closed | AL9: 2026-04-02 | AM9: JE JMX OU | AN9: 202300058566 | AO9: 01-APR-26 | AP9: 22122.35 | AQ9: USD | AR9: 1908-1E90003RN | AS9: 600 | AT9: EA | AU9: 40151503 | AV9: Bombas centrífugas | AW9: H87 | AX9: Pieza | AY9: 8413309902 | AZ9: Para agua | BC9: FG-R-2180LE25 | BD9: 5775 | BE9: 5775 | BG9: {=_xlfn.LET(_xlpm.list,$BC$9:$BC$33,_xlpm.data,_xlfn.CHOOSECOLS($B$8:$AZ$263,1,2,3,13,14,4,43,44,5),_xlpm.out,_xlfn.DROP(_xlfn.REDUCE("",_xlfn.SEQUENCE(ROWS(_xlpm.list)),_xlfn.LAMBDA(_xlpm.a,_xlpm.b,_xlfn.VSTACK(_xlpm.a,_xlfn._xlws.FILTER(_xlpm.data,_xlfn.CHOOSECOLS(_xlpm.data,3)=INDEX(_xlpm.list,_xlpm.b),"No data")))),1),_xlpm.out)} -> Outbound | BH9: Land | BI9: FG-R-2180LE25 | BJ9: JOHNSON ELECTRIC NORTH AMERICA, INC. | BK9: (TDS) Transcontinental Distribution Services, Inc 14213 Transportation Ave | BL9: M23 | BM9: 1908-1E90003RN | BN9: 600 | BO9: 1098.8 | BP9: =BO9/SUMIFS($BO:$BO,$BI:$BI,BI9) -> 0.061965597 | BQ9: =_xlfn.XLOOKUP(BI9,$BC:$BC,$BE:$BE)*BP9 -> 357.85133 | BS9: {=_xlfn.DROP(_xlfn.GROUPBY($BL$8:$BL$263,BQ8:BQ263,_xlfn.HSTACK(_xleta.SUM,_xleta.PERCENTOF),1,1),1)} -> M01 | BT9: 27091.89 | BU9: 0.21335361 | BW9: =BT9-BV9 -> 27091.89 | BX9: =BW9/BW$14 -> 0.28523434
B10: Outbound | C10: Land | D10: {=_xlfn.REGEXEXTRACT(G10,"FG-R-\d{4}LE\d{2}")} -> FG-R-2180LE25 | E10: M23 | F10: {=_xlfn.SWITCH(TRUE,T10>0,T10,Z10)} -> 1538.32 | G10: FG-R-2180LE25.M46-M45-2 | H10: 3 BROTHERS | I10: H06059 | J10: 2026/04/01 00:00:00 | K10: 2026/04/01 00:00:00 | L10: FG-R-2180LE25.M46-M45 | M10: UL-5606471 | N10: JOHNSON ELECTRIC NORTH AMERICA, INC. | O10: (TDS) Transcontinental Distribution Services, Inc 14213 Transportation Ave | P10: Johnson Electric Group Mexico, S. de R. L. de C.V. | Q10: Boulevard Morelos # 1109,Mega Parque Industrial Aeropuerto de Calera,98519, Calera | R10: 7 | S10: 1391.32 | T10: 1538.32 | U10: 140 | V10: 1218.84 | W10: 1391.32 | X10: 0 | Y10: 0 | Z10: 0 | AA10: 0 | AB10: 0 | AC10: 0 | AD10: 0 | AE10: 7 | AF10: 0 | AG10: 0 | AH10: 7 | AI10: 0 | AJ10: 6171313 | AK10: Closed | AL10: 2026-04-02 | AM10: JE JMX OU | AN10: 202300058567 | AO10: 01-APR-26 | AP10: 30971.29 | AQ10: USD | AR10: 1908-1E90003RN | AS10: 840 | AT10: EA | AU10: 40151503 | AV10: Bombas centrífugas | AW10: H87 | AX10: Pieza | AY10: 8413309902 | AZ10: Para agua | BC10: FG-R-2181LE25 | BD10: 4545 | BE10: 4545 | BG10: Outbound | BH10: Land | BI10: FG-R-2180LE25 | BJ10: JOHNSON ELECTRIC NORTH AMERICA, INC. | BK10: (TDS) Transcontinental Distribution Services, Inc 14213 Transportation Ave | BL10: M23 | BM10: 1908-1E90003RN | BN10: 840 | BO10: 1538.32 | BP10: =BO10/SUMIFS($BO:$BO,$BI:$BI,BI10) -> 0.086751836 | BQ10: =_xlfn.XLOOKUP(BI10,$BC:$BC,$BE:$BE)*BP10 -> 500.99186 | BS10: M19 | BT10: 52061.002 | BU10: 0.40998995 | BV10: 32000 | BW10: =BT10-BV10 -> 20061.002 | BX10: =BW10/BW$14 -> 0.21121031
B11: Outbound | C11: Land | D11: {=_xlfn.REGEXEXTRACT(G11,"FG-R-\d{4}LE\d{2}")} -> FG-R-2180LE25 | E11: M23 | F11: {=_xlfn.SWITCH(TRUE,T11>0,T11,Z11)} -> 80.628 | G11: FG-R-2180LE25.M46-M45-2 | H11: 3 BROTHERS | I11: H06059 | J11: 2026/04/01 00:00:00 | K11: 2026/04/01 00:00:00 | L11: FG-R-2180LE25.M46-M45 | M11: UL-5606471 | N11: JOHNSON ELECTRIC NORTH AMERICA, INC. | O11: (TDS) Transcontinental Distribution Services, Inc 14213 Transportation Ave | P11: Johnson Electric Group Mexico, S. de R. L. de C.V. | Q11: Boulevard Morelos # 1109,Mega Parque Industrial Aeropuerto de Calera,98519, Calera | R11: 0 | S11: 0 | T11: 0 | U11: 0 | V11: 0 | W11: 0 | X11: 1 | Y11: 59.628 | Z11: 80.628 | AA11: 6 | AB11: 52.236 | AC11: 59.628 | AD11: 1 | AE11: 0 | AF11: 0 | AG11: 0 | AH11: 1 | AI11: 0 | AJ11: 6171332 | AK11: Closed | AL11: 2026-04-02 | AM11: JE JMX OU | AN11: 202300058569 | AO11: 01-APR-26 | AP11: 1455.55 | AQ11: USD | AR11: 1908-1E90003R1 | AS11: 36 | AT11: EA | AU11: 40151503 | AV11: Bombas centrífugas | AW11: H87 | AX11: Pieza | AY11: 8413309902 | AZ11: Para agua | BC11: FG-R-2182LE25 | BD11: 6025 | BE11: 6025 | BG11: Outbound | BH11: Land | BI11: FG-R-2180LE25 | BJ11: JOHNSON ELECTRIC NORTH AMERICA, INC. | BK11: (TDS) Transcontinental Distribution Services, Inc 14213 Transportation Ave | BL11: M23 | BM11: 1908-1E90003R1 | BN11: 36 | BO11: 80.628 | BP11: =BO11/SUMIFS($BO:$BO,$BI:$BI,BI11) -> 0.0045469259 | BQ11: =_xlfn.XLOOKUP(BI11,$BC:$BC,$BE:$BE)*BP11 -> 26.258497 | BS11: M23 | BT11: 4022.6962 | BU11: 0.031679472 | BW11: =BT11-BV11 -> 4022.6962 | BX11: =BW11/BW$14 -> 0.042352568
B12: Outbound | C12: Land | D12: {=_xlfn.REGEXEXTRACT(G12,"FG-R-\d{4}LE\d{2}")} -> FG-R-2180LE25 | E12: M45 | F12: {=_xlfn.SWITCH(TRUE,T12>0,T12,Z12)} -> 5299.296 | G12: FG-R-2180LE25.M46-M45 | H12: 3 BROTHERS | I12: H06059 | J12: 2026/04/01 00:00:00 | K12: 2026/04/01 00:00:00 | L12: FG-R-2180LE25.M46-M45 | M12: UL-5606471 | N12: JOHNSON ELECTRIC NORTH AMERICA, INC. | O12: APX WH 6001 GLOBAL DISTRIBUTION WAY LOUISVILLE, KY 40228 | P12: Johnson Electric Group Mexico, S. de R. L. de C.V. | Q12: Boulevard Morelos # 1109,Mega Parque Industrial Aeropuerto de Calera,98519, Calera | R12: 12 | S12: 5077.296 | T12: 5299.296 | U12: 504 | V12: 4886.784 | W12: 5077.296 | X12: 0 | Y12: 0 | Z12: 0 | AA12: 0 | AB12: 0 | AC12: 0 | AD12: 12 | AE12: 0 | AF12: 0 | AG12: 12 | AH12: 0 | AI12: 0 | AJ12: 6171300 | AK12: Closed | AL12: 2026-04-02 | AM12: JE JMX OU | AN12: 202300058563 | AO12: 01-APR-26 | AP12: 36914.88 | AQ12: USD | AR12: 1999-1E30016EU | AS12: 6048 | AT12: EA | AU12: 40151500 | AV12: Bombas | AW12: H87 | AX12: Pieza | AY12: 8413709999 | AZ12: Las demás | BC12: FG-R-2183LE25 | BD12: 5197 | BE12: 5197 | BG12: Outbound | BH12: Land | BI12: FG-R-2180LE25 | BJ12: JOHNSON ELECTRIC NORTH AMERICA, INC. | BK12: APX WH 6001 GLOBAL DISTRIBUTION WAY LOUISVILLE, KY 40228 | BL12: M45 | BM12: 1999-1E30016EU | BN12: 6048 | BO12: 5299.296 | BP12: =BO12/SUMIFS($BO:$BO,$BI:$BI,BI12) -> 0.29884787 | BQ12: =_xlfn.XLOOKUP(BI12,$BC:$BC,$BE:$BE)*BP12 -> 1725.8465 | BS12: M45 | BT12: 40087.217 | BU12: 0.3156942 | BW12: =BT12-BV12 -> 40087.217 | BX12: =BW12/BW$14 -> 0.42205439
B13: Outbound | C13: Land | D13: {=_xlfn.REGEXEXTRACT(G13,"FG-R-\d{4}LE\d{2}")} -> FG-R-2180LE25 | E13: M45 | F13: {=_xlfn.SWITCH(TRUE,T13>0,T13,Z13)} -> 3974.472 | G13: FG-R-2180LE25.M46-M45 | H13: 3 BROTHERS | I13: H06059 | J13: 2026/04/01 00:00:00 | K13: 2026/04/01 00:00:00 | L13: FG-R-2180LE25.M46-M45 | M13: UL-5606471 | N13: JOHNSON ELECTRIC NORTH AMERICA, INC. | O13: APX WH 6001 GLOBAL DISTRIBUTION WAY LOUISVILLE, KY 40228 | P13: Johnson Electric Group Mexico, S. de R. L. de C.V. | Q13: Boulevard Morelos # 1109,Mega Parque Industrial Aeropuerto de Calera,98519, Calera | R13: 9 | S13: 3807.972 | T13: 3974.472 | U13: 378 | V13: 3665.088 | W13: 3807.972 | X13: 0 | Y13: 0 | Z13: 0 | AA13: 0 | AB13: 0 | AC13: 0 | AD13: 9 | AE13: 0 | AF13: 0 | AG13: 9 | AH13: 0 | AI13: 0 | AJ13: 6171301 | AK13: Closed | AL13: 2026-04-02 | AM13: JE JMX OU | AN13: 202300058564 | AO13: 01-APR-26 | AP13: 27686.16 | AQ13: USD | AR13: 1999-1E30016EU | AS13: 4536 | AT13: EA | AU13: 40151500 | AV13: Bombas | AW13: H87 | AX13: Pieza | AY13: 8413709999 | AZ13: Las demás | BC13: FG-R-2184LE25 | BD13: 906.60277 | BE13: 4918.7603 | BG13: Outbound | BH13: Land | BI13: FG-R-2180LE25 | BJ13: JOHNSON ELECTRIC NORTH AMERICA, INC. | BK13: APX WH 6001 GLOBAL DISTRIBUTION WAY LOUISVILLE, KY 40228 | BL13: M45 | BM13: 1999-1E30016EU | BN13: 4536 | BO13: 3974.472 | BP13: =BO13/SUMIFS($BO:$BO,$BI:$BI,BI13) -> 0.2241359 | BQ13: =_xlfn.XLOOKUP(BI13,$BC:$BC,$BE:$BE)*BP13 -> 1294.3848 | BS13: M46 | BT13: 3718.3599 | BU13: 0.029282767 | BW13: =BT13-BV13 -> 3718.3599 | BX13: =BW13/BW$14 -> 0.039148392
B14: Outbound | C14: Land | D14: {=_xlfn.REGEXEXTRACT(G14,"FG-R-\d{4}LE\d{2}")} -> FG-R-2180LE25 | E14: M45 | F14: {=_xlfn.SWITCH(TRUE,T14>0,T14,Z14)} -> 5740.904 | G14: FG-R-2180LE25.M46-M45 | H14: 3 BROTHERS | I14: H06059 | J14: 2026/04/01 00:00:00 | K14: 2026/04/01 00:00:00 | L14: FG-R-2180LE25.M46-M45 | M14: UL-5606471 | N14: JOHNSON ELECTRIC NORTH AMERICA, INC. | O14: APX WH 6001 GLOBAL DISTRIBUTION WAY LOUISVILLE, KY 40228 | P14: Johnson Electric Group Mexico, S. de R. L. de C.V. | Q14: Boulevard Morelos # 1109,Mega Parque Industrial Aeropuerto de Calera,98519, Calera | R14: 13 | S14: 5500.404 | T14: 5740.904 | U14: 546 | V14: 5294.016 | W14: 5500.404 | X14: 0 | Y14: 0 | Z14: 0 | AA14: 0 | AB14: 0 | AC14: 0 | AD14: 13 | AE14: 0 | AF14: 0 | AG14: 13 | AH14: 0 | AI14: 0 | AJ14: 6171302 | AK14: Closed | AL14: 2026-04-02 | AM14: JE JMX OU | AN14: 202300058565 | AO14: 01-APR-26 | AP14: 39991.12 | AQ14: USD | AR14: 1999-1E30016EU | AS14: 6552 | AT14: EA | AU14: 40151500 | AV14: Bombas | AW14: H87 | AX14: Pieza | AY14: 8413709999 | AZ14: Las demás | BC14: FG-R-2186LE26 | BD14: 5775 | BE14: 5775 | BG14: Outbound | BH14: Land | BI14: FG-R-2180LE25 | BJ14: JOHNSON ELECTRIC NORTH AMERICA, INC. | BK14: APX WH 6001 GLOBAL DISTRIBUTION WAY LOUISVILLE, KY 40228 | BL14: M45 | BM14: 1999-1E30016EU | BN14: 6552 | BO14: 5740.904 | BP14: =BO14/SUMIFS($BO:$BO,$BI:$BI,BI14) -> 0.32375186 | BQ14: =_xlfn.XLOOKUP(BI14,$BC:$BC,$BE:$BE)*BP14 -> 1869.667 | BS14: Total | BT14: 126981.16 | BU14: 1 | BW14: =SUM(BW9:BW13) -> 94981.164
B15: Outbound | C15: Land | D15: {=_xlfn.REGEXEXTRACT(G15,"FG-R-\d{4}LE\d{2}")} -> FG-R-2181LE25 | E15: M01 | F15: {=_xlfn.SWITCH(TRUE,T15>0,T15,Z15)} -> 1161.36 | G15: FG-R-2181LE25.M01-M45 | H15: 3 BROTHERS | I15: 560602 | J15: 2026/04/03 00:00:00 | K15: 2026/04/03 00:00:00 | L15: FG-R-2181LE25.M01-M45 | M15: UL-5606473 | N15: JOHNSON ELECTRIC NORTH AMERICA, INC. | O15: Memphis Distribution Services 3893 Crowfarn | P15: Johnson Electric Group Mexico, S. de R. L. de C.V. | Q15: Boulevard Morelos # 1109,Mega Parque Industrial Aeropuerto de Calera,98519, Calera | R15: 2 | S15: 1107.36 | T15: 1161.36 | U15: 160 | V15: 432 | W15: 1107.36 | X15: 0 | Y15: 0 | Z15: 0 | AA15: 0 | AB15: 0 | AC15: 0 | AD15: 2 | AE15: 0 | AF15: 0 | AG15: 2 | AH15: 0 | AI15: 0 | AJ15: 6173338 | AK15: Closed | AL15: 2026-04-03 | AM15: JE JMX OU | AN15: 202300058592 | AO15: 02-APR-26 | AP15: 7368.28 | AQ15: USD | AR15: 1999-1WP0063AN | AS15: 4000 | AT15: EA | AU15: 40151500 | AV15: Bombas | AW15: H87 | AX15: Pieza | AY15: 8413700700 | AZ15: Bombas de agua, reconocibles como diseñadas exclusivamente para el sistema de limpiaparabrisas, para uso automotriz | BC15: FG-R-2187LE26 | BD15: 5197 | BE15: 5197 | BG15: Outbound | BH15: Land | BI15: FG-R-2181LE25 | BJ15: JOHNSON ELECTRIC NORTH AMERICA, INC. | BK15: Memphis Distribution Services 3893 Crowfarn | BL15: M01 | BM15: 1999-1WP0063AN | BN15: 4000 | BO15: 1161.36 | BP15: =BO15/SUMIFS($BO:$BO,$BI:$BI,BI15) -> 0.20079361 | BQ15: =_xlfn.XLOOKUP(BI15,$BC:$BC,$BE:$BE)*BP15 -> 912.60697
B16: Outbound | C16: Land | D16: {=_xlfn.REGEXEXTRACT(G16,"FG-R-\d{4}LE\d{2}")} -> FG-R-2181LE25 | E16: M01 | F16: {=_xlfn.SWITCH(TRUE,T16>0,T16,Z16)} -> 825.724 | G16: FG-R-2181LE25.M01-M45 | H16: 3 BROTHERS | I16: 560602 | J16: 2026/04/03 00:00:00 | K16: 2026/04/03 00:00:00 | L16: FG-R-2181LE25.M01-M45 | M16: UL-5606473 | N16: JOHNSON ELECTRIC NORTH AMERICA, INC. | O16: Memphis Distribution Services 3893 Crowfarn | P16: Johnson Electric Group Mexico, S. de R. L. de C.V. | Q16: Boulevard Morelos # 1109,Mega Parque Industrial Aeropuerto de Calera,98519, Calera | R16: 2 | S16: 788.724 | T16: 825.724 | U16: 180 | V16: 734.4 | W16: 788.724 | X16: 0 | Y16: 0 | Z16: 0 | AA16: 0 | AB16: 0 | AC16: 0 | AD16: 2 | AE16: 0 | AF16: 0 | AG16: 2 | AH16: 0 | AI16: 0 | AJ16: 6173300 | AK16: Closed | AL16: 2026-04-03 | AM16: JE JMX OU | AN16: 202300058580 | AO16: 02-APR-26 | AP16: 11450.02 | AQ16: USD | AR16: 1999-1WP0045AN | AS16: 7200 | AT16: EA | AU16: 40151500 | AV16: Bombas | AW16: H87 | AX16: Pieza | AY16: 8413700700 | AZ16: Bombas de agua, reconocibles como diseñadas exclusivamente para el sistema de limpiaparabrisas, para uso automotriz | BC16: FG-R-2188LE26 | BD16: 4545 | BE16: 4545 | BG16: Outbound | BH16: Land | BI16: FG-R-2181LE25 | BJ16: JOHNSON ELECTRIC NORTH AMERICA, INC. | BK16: Memphis Distribution Services 3893 Crowfarn | BL16: M01 | BM16: 1999-1WP0045AN | BN16: 7200 | BO16: 825.724 | BP16: =BO16/SUMIFS($BO:$BO,$BI:$BI,BI16) -> 0.14276375 | BQ16: =_xlfn.XLOOKUP(BI16,$BC:$BC,$BE:$BE)*BP16 -> 648.86123
B17: Outbound | C17: Land | D17: {=_xlfn.REGEXEXTRACT(G17,"FG-R-\d{4}LE\d{2}")} -> FG-R-2181LE25 | E17: M01 | F17: {=_xlfn.SWITCH(TRUE,T17>0,T17,Z17)} -> 311.113 | G17: FG-R-2181LE25.M01-M45 | H17: 3 BROTHERS | I17: 560602 | J17: 2026/04/03 00:00:00 | K17: 2026/04/03 00:00:00 | L17: FG-R-2181LE25.M01-M45 | M17: UL-5606473 | N17: JOHNSON ELECTRIC NORTH AMERICA, INC. | O17: Memphis Distribution Services 3893 Crowfarn | P17: Johnson Electric Group Mexico, S. de R. L. de C.V. | Q17: Boulevard Morelos # 1109,Mega Parque Industrial Aeropuerto de Calera,98519, Calera | R17: 1 | S17: 292.113 | T17: 311.113 | U17: 90 | V17: 250.56 | W17: 292.113 | X17: 0 | Y17: 0 | Z17: 0 | AA17: 0 | AB17: 0 | AC17: 0 | AD17: 1 | AE17: 0 | AF17: 0 | AG17: 1 | AH17: 0 | AI17: 0 | AJ17: 6173298 | AK17: Closed | AL17: 2026-04-03 | AM17: JE JMX OU | AN17: 202300058579 | AO17: 02-APR-26 | AP17: 4034.34 | AQ17: USD | AR17: 1999-1WP0046AN | AS17: 2160 | AT17: EA | AU17: 40151500 | AV17: Bombas | AW17: H87 | AX17: Pieza | AY17: 8413700700 | AZ17: Bombas de agua, reconocibles como diseñadas exclusivamente para el sistema de limpiaparabrisas, para uso automotriz | BC17: FG-R-2189LE26 | BD17: 6025 | BE17: 6025 | BG17: Outbound | BH17: Land | BI17: FG-R-2181LE25 | BJ17: JOHNSON ELECTRIC NORTH AMERICA, INC. | BK17: Memphis Distribution Services 3893 Crowfarn | BL17: M01 | BM17: 1999-1WP0046AN | BN17: 2160 | BO17: 311.113 | BP17: =BO17/SUMIFS($BO:$BO,$BI:$BI,BI17) -> 0.053789956 | BQ17: =_xlfn.XLOOKUP(BI17,$BC:$BC,$BE:$BE)*BP17 -> 244.47535
B18: Outbound | C18: Land | D18: {=_xlfn.REGEXEXTRACT(G18,"FG-R-\d{4}LE\d{2}")} -> FG-R-2181LE25 | E18: M01 | F18: {=_xlfn.SWITCH(TRUE,T18>0,T18,Z18)} -> 329.88 | G18: FG-R-2181LE25.M01-M45 | H18: 3 BROTHERS | I18: 560602 | J18: 2026/04/03 00:00:00 | K18: 2026/04/03 00:00:00 | L18: FG-R-2181LE25.M01-M45 | M18: UL-5606473 | N18: JOHNSON ELECTRIC NORTH AMERICA, INC. | O18: Memphis Distribution Services 3893 Crowfarn | P18: Johnson Electric Group Mexico, S. de R. L. de C.V. | Q18: Boulevard Morelos # 1109,Mega Parque Industrial Aeropuerto de Calera,98519, Calera | R18: 3 | S18: 254.88 | T18: 329.88 | U18: 0 | V18: 254.88 | W18: 254.88 | X18: 0 | Y18: 0 | Z18: 0 | AA18: 0 | AB18: 0 | AC18: 0 | AD18: 3 | AE18: 0 | AF18: 0 | AG18: 3 | AH18: 0 | AI18: 0 | AJ18: 6173279 | AK18: Closed | AL18: 2026-04-03 | AM18: JE JMX OU | AN18: 202300058581 | AO18: 02-APR-26 | AP18: 11555.28 | AQ18: USD | AR18: 1916-1010002EP/MX | AS18: 4320 | AT18: EA | AU18: 26101200 | AV18: Motores eléctricos de corriente directa DC | AW18: H87 | AX18: Pieza | AY18: 8501101004 | AZ18: Accionados exclusivamente por corriente continua | BC18: FG-R-2190LE26 | BD18: 5197 | BE18: 5197 | BG18: Outbound | BH18: Land | BI18: FG-R-2181LE25 | BJ18: JOHNSON ELECTRIC NORTH AMERICA, INC. | BK18: Memphis Distribution Services 3893 Crowfarn | BL18: M01 | BM18: 1916-1010002EP/MX | BN18: 4320 | BO18: 329.88 | BP18: =BO18/SUMIFS($BO:$BO,$BI:$BI,BI18) -> 0.057034681 | BQ18: =_xlfn.XLOOKUP(BI18,$BC:$BC,$BE:$BE)*BP18 -> 259.22262
B19: Outbound | C19: Land | D19: {=_xlfn.REGEXEXTRACT(G19,"FG-R-\d{4}LE\d{2}")} -> FG-R-2181LE25 | E19: M01 | F19: {=_xlfn.SWITCH(TRUE,T19>0,T19,Z19)} -> 329.88 | G19: FG-R-2181LE25.M01-M45 | H19: 3 BROTHERS | I19: 560602 | J19: 2026/04/03 00:00:00 | K19: 2026/04/03 00:00:00 | L19: FG-R-2181LE25.M01-M45 | M19: UL-5606473 | N19: JOHNSON ELECTRIC NORTH AMERICA, INC. | O19: Memphis Distribution Services 3893 Crowfarn | P19: Johnson Electric Group Mexico, S. de R. L. de C.V. | Q19: Boulevard Morelos # 1109,Mega Parque Industrial Aeropuerto de Calera,98519, Calera | R19: 3 | S19: 254.88 | T19: 329.88 | U19: 0 | V19: 254.88 | W19: 254.88 | X19: 0 | Y19: 0 | Z19: 0 | AA19: 0 | AB19: 0 | AC19: 0 | AD19: 3 | AE19: 0 | AF19: 0 | AG19: 3 | AH19: 0 | AI19: 0 | AJ19: 6173280 | AK19: Closed | AL19: 2026-04-03 | AM19: JE JMX OU | AN19: 202300058582 | AO19: 02-APR-26 | AP19: 11555.28 | AQ19: USD | AR19: 1916-1010002EP/MX | AS19: 4320 | AT19: EA | AU19: 26101200 | AV19: Motores eléctricos de corriente directa DC | AW19: H87 | AX19: Pieza | AY19: 8501101004 | AZ19: Accionados exclusivamente por corriente continua | BC19: FG-R-2191LE26 | BD19: 0 | BE19: 4918.7603 | BG19: Outbound | BH19: Land | BI19: FG-R-2181LE25 | BJ19: JOHNSON ELECTRIC NORTH AMERICA, INC. | BK19: Memphis Distribution Services 3893 Crowfarn | BL19: M01 | BM19: 1916-1010002EP/MX | BN19: 4320 | BO19: 329.88 | BP19: =BO19/SUMIFS($BO:$BO,$BI:$BI,BI19) -> 0.057034681 | BQ19: =_xlfn.XLOOKUP(BI19,$BC:$BC,$BE:$BE)*BP19 -> 259.22262
B20: Outbound | C20: Land | D20: {=_xlfn.REGEXEXTRACT(G20,"FG-R-\d{4}LE\d{2}")} -> FG-R-2181LE25 | E20: M01 | F20: {=_xlfn.SWITCH(TRUE,T20>0,T20,Z20)} -> 297.91232 | G20: FG-R-2181LE25.M01-M45 | H20: 3 BROTHERS | I20: 560602 | J20: 2026/04/03 00:00:00 | K20: 2026/04/03 00:00:00 | L20: FG-R-2181LE25.M01-M45 | M20: UL-5606473 | N20: JOHNSON ELECTRIC NORTH AMERICA, INC. | O20: Memphis Distribution Services 3893 Crowfarn | P20: Johnson Electric Group Mexico, S. de R. L. de C.V. | Q20: Boulevard Morelos # 1109,Mega Parque Industrial Aeropuerto de Calera,98519, Calera | R20: 1 | S20: 278.91232 | T20: 297.91232 | U20: 70 | V20: 278.88 | W20: 278.91232 | X20: 0 | Y20: 0 | Z20: 0 | AA20: 0 | AB20: 0 | AC20: 0 | AD20: 1 | AE20: 0 | AF20: 0 | AG20: 1 | AH20: 0 | AI20: 0 | AJ20: 6173294 | AK20: Closed | AL20: 2026-04-03 | AM20: JE JMX OU | AN20: 202300058576 | AO20: 02-APR-26 | AP20: 5376.11 | AQ20: USD | AR20: 1999-1WP0105EN | AS20: 2100 | AT20: EA | AU20: 25171506 | AV20: Bomba de lava parabrisas | AW20: H87 | AX20: Pieza | AY20: 8413700700 | AZ20: Bombas de agua, reconocibles como diseñadas exclusivamente para el sistema de limpiaparabrisas, para uso automotriz | BC20: FG-R-2192LE26 | BD20: 316.85912 | BE20: 4918.7603 | BG20: Outbound | BH20: Land | BI20: FG-R-2181LE25 | BJ20: JOHNSON ELECTRIC NORTH AMERICA, INC. | BK20: Memphis Distribution Services 3893 Crowfarn | BL20: M01 | BM20: 1999-1WP0105EN | BN20: 2100 | BO20: 297.91232 | BP20: =BO20/SUMIFS($BO:$BO,$BI:$BI,BI20) -> 0.051507621 | BQ20: =_xlfn.XLOOKUP(BI20,$BC:$BC,$BE:$BE)*BP20 -> 234.10214
B21: Outbound | C21: Land | D21: {=_xlfn.REGEXEXTRACT(G21,"FG-R-\d{4}LE\d{2}")} -> FG-R-2181LE25 | E21: M01 | F21: {=_xlfn.SWITCH(TRUE,T21>0,T21,Z21)} -> 117.16 | G21: FG-R-2181LE25.M01-M45 | H21: 3 BROTHERS | I21: 560602 | J21: 2026/04/03 00:00:00 | K21: 2026/04/03 00:00:00 | L21: FG-R-2181LE25.M01-M45 | M21: UL-5606473 | N21: JOHNSON ELECTRIC NORTH AMERICA, INC. | O21: Memphis Distribution Services 3893 Crowfarn | P21: Johnson Electric Group Mexico, S. de R. L. de C.V. | Q21: Boulevard Morelos # 1109,Mega Parque Industrial Aeropuerto de Calera,98519, Calera | R21: 1 | S21: 92.16 | T21: 117.16 | U21: 0 | V21: 92.16 | W21: 92.16 | X21: 0 | Y21: 0 | Z21: 0 | AA21: 0 | AB21: 0 | AC21: 0 | AD21: 1 | AE21: 0 | AF21: 0 | AG21: 1 | AH21: 0 | AI21: 0 | AJ21: 6173285 | AK21: Closed | AL21: 2026-04-03 | AM21: JE JMX OU | AN21: 202300058590 | AO21: 02-APR-26 | AP21: 3998.61 | AQ21: USD | AR21: 1916-1010004EN | AS21: 1440 | AT21: EA | AU21: 26101200 | AV21: Motores eléctricos de corriente directa DC | AW21: H87 | AX21: Pieza | AY21: 8501101004 | AZ21: Accionados exclusivamente por corriente continua | BC21: FG-R-2193LE26 | BD21: 0 | BE21: 4918.7603 | BG21: Outbound | BH21: Land | BI21: FG-R-2181LE25 | BJ21: JOHNSON ELECTRIC NORTH AMERICA, INC. | BK21: Memphis Distribution Services 3893 Crowfarn | BL21: M01 | BM21: 1916-1010004EN | BN21: 1440 | BO21: 117.16 | BP21: =BO21/SUMIFS($BO:$BO,$BI:$BI,BI21) -> 0.020256406 | BQ21: =_xlfn.XLOOKUP(BI21,$BC:$BC,$BE:$BE)*BP21 -> 92.065365
B22: Outbound | C22: Land | D22: {=_xlfn.REGEXEXTRACT(G22,"FG-R-\d{4}LE\d{2}")} -> FG-R-2181LE25 | E22: M01 | F22: {=_xlfn.SWITCH(TRUE,T22>0,T22,Z22)} -> 504.6 | G22: FG-R-2181LE25.M01-M45 | H22: 3 BROTHERS | I22: 560602 | J22: 2026/04/03 00:00:00 | K22: 2026/04/03 00:00:00 | L22: FG-R-2181LE25.M01-M45 | M22: UL-5606473 | N22: JOHNSON ELECTRIC NORTH AMERICA, INC. | O22: Memphis Distribution Services 3893 Crowfarn | P22: Johnson Electric Group Mexico, S. de R. L. de C.V. | Q22: Boulevard Morelos # 1109,Mega Parque Industrial Aeropuerto de Calera,98519, Calera | R22: 1 | S22: 477.6 | T22: 504.6 | U22: 60 | V22: 441.6 | W22: 477.6 | X22: 0 | Y22: 0 | Z22: 0 | AA22: 0 | AB22: 0 | AC22: 0 | AD22: 1 | AE22: 0 | AF22: 0 | AG22: 1 | AH22: 0 | AI22: 0 | AJ22: 6173297 | AK22: Closed | AL22: 2026-04-03 | AM22: JE JMX OU | AN22: 202300058578 | AO22: 02-APR-26 | AP22: 7290.29 | AQ22: USD | AR22: 1999-1WP0055AN | AS22: 4800 | AT22: EA | AU22: 40151500 | AV22: Bombas | AW22: H87 | AX22: Pieza | AY22: 8413700700 | AZ22: Bombas de agua, reconocibles como diseñadas exclusivamente para el sistema de limpiaparabrisas, para uso automotriz | BC22: FG-R-2194LE26 | BD22: 0 | BE22: 4918.7603 | BG22: Outbound | BH22: Land | BI22: FG-R-2181LE25 | BJ22: JOHNSON ELECTRIC NORTH AMERICA, INC. | BK22: Memphis Distribution Services 3893 Crowfarn | BL22: M01 | BM22: 1999-1WP0055AN | BN22: 4800 | BO22: 504.6 | BP22: =BO22/SUMIFS($BO:$BO,$BI:$BI,BI22) -> 0.087242937 | BQ22: =_xlfn.XLOOKUP(BI22,$BC:$BC,$BE:$BE)*BP22 -> 396.51915
B23: Outbound | C23: Land | D23: {=_xlfn.REGEXEXTRACT(G23,"FG-R-\d{4}LE\d{2}")} -> FG-R-2181LE25 | E23: M01 | F23: {=_xlfn.SWITCH(TRUE,T23>0,T23,Z23)} -> 633.24 | G23: FG-R-2181LE25.M01-M45 | H23: 3 BROTHERS | I23: 560602 | J23: 2026/04/03 00:00:00 | K23: 2026/04/03 00:00:00 | L23: FG-R-2181LE25.M01-M45 | M23: UL-5606473 | N23: JOHNSON ELECTRIC NORTH AMERICA, INC. | O23: Memphis Distribution Services 3893 Crowfarn | P23: Johnson Electric Group Mexico, S. de R. L. de C.V. | Q23: Boulevard Morelos # 1109,Mega Parque Industrial Aeropuerto de Calera,98519, Calera | R23: 1 | S23: 606.24 | T23: 633.24 | U23: 60 | V23: 570.24 | W23: 606.24 | X23: 0 | Y23: 0 | Z23: 0 | AA23: 0 | AB23: 0 | AC23: 0 | AD23: 1 | AE23: 0 | AF23: 0 | AG23: 1 | AH23: 0 | AI23: 0 | AJ23: 6173296 | AK23: Closed | AL23: 2026-04-03 | AM23: JE JMX OU | AN23: 202300058577 | AO23: 02-APR-26 | AP23: 10229.52 | AQ23: USD | AR23: 1999-1WP0113EN | AS23: 4800 | AT23: EA | AU23: 25171506 | AV23: Bomba de lava parabrisas | AW23: H87 | AX23: Pieza | AY23: 8413700700 | AZ23: Bombas de agua, reconocibles como diseñadas exclusivamente para el sistema de limpiaparabrisas, para uso automotriz | BC23: FG-R-2195LE26 | BD23: 0 | BE23: 4918.7603 | BG23: Outbound | BH23: Land | BI23: FG-R-2181LE25 | BJ23: JOHNSON ELECTRIC NORTH AMERICA, INC. | BK23: Memphis Distribution Services 3893 Crowfarn | BL23: M01 | BM23: 1999-1WP0113EN | BN23: 4800 | BO23: 633.24 | BP23: =BO23/SUMIFS($BO:$BO,$BI:$BI,BI23) -> 0.10948418 | BQ23: =_xlfn.XLOOKUP(BI23,$BC:$BC,$BE:$BE)*BP23 -> 497.6056
B24: Outbound | C24: Land | D24: {=_xlfn.REGEXEXTRACT(G24,"FG-R-\d{4}LE\d{2}")} -> FG-R-2181LE25 | E24: M01 | F24: {=_xlfn.SWITCH(TRUE,T24>0,T24,Z24)} -> 439.84 | G24: FG-R-2181LE25.M01-M45 | H24: 3 BROTHERS | I24: 560602 | J24: 2026/04/03 00:00:00 | K24: 2026/04/03 00:00:00 | L24: FG-R-2181LE25.M01-M45 | M24: UL-5606473 | N24: JOHNSON ELECTRIC NORTH AMERICA, INC. | O24: Memphis Distribution Services 3893 Crowfarn | P24: Johnson Electric Group Mexico, S. de R. L. de C.V. | Q24: Boulevard Morelos # 1109,Mega Parque Industrial Aeropuerto de Calera,98519, Calera | R24: 4 | S24: 339.84 | T24: 439.84 | U24: 0 | V24: 339.84 | W24: 339.84 | X24: 0 | Y24: 0 | Z24: 0 | AA24: 0 | AB24: 0 | AC24: 0 | AD24: 4 | AE24: 0 | AF24: 0 | AG24: 4 | AH24: 0 | AI24: 0 | AJ24: 6173283 | AK24: Closed | AL24: 2026-04-03 | AM24: JE JMX OU | AN24: 202300058588 | AO24: 02-APR-26 | AP24: 15407.04 | AQ24: USD | AR24: 1916-1010002EP/MX | AS24: 5760 | AT24: EA | AU24: 26101200 | AV24: Motores eléctricos de corriente directa DC | AW24: H87 | AX24: Pieza | AY24: 8501101004 | AZ24: Accionados exclusivamente por corriente continua | BC24: FG-R-2197LE26 | BD24: 0 | BE24: 4918.7603 | BG24: Outbound | BH24: Land | BI24: FG-R-2181LE25 | BJ24: JOHNSON ELECTRIC NORTH AMERICA, INC. | BK24: Memphis Distribution Services 3893 Crowfarn | BL24: M01 | BM24: 1916-1010002EP/MX | BN24: 5760 | BO24: 439.84 | BP24: =BO24/SUMIFS($BO:$BO,$BI:$BI,BI24) -> 0.076046241 | BQ24: =_xlfn.XLOOKUP(BI24,$BC:$BC,$BE:$BE)*BP24 -> 345.63017
B25: Outbound | C25: Land | D25: {=_xlfn.REGEXEXTRACT(G25,"FG-R-\d{4}LE\d{2}")} -> FG-R-2181LE25 | E25: M01 | F25: {=_xlfn.SWITCH(TRUE,T25>0,T25,Z25)} -> 585.8 | G25: FG-R-2181LE25.M01-M45 | H25: 3 BROTHERS | I25: 560602 | J25: 2026/04/03 00:00:00 | K25: 2026/04/03 00:00:00 | L25: FG-R-2181LE25.M01-M45 | M25: UL-5606473 | N25: JOHNSON ELECTRIC NORTH AMERICA, INC. | O25: Memphis Distribution Services 3893 Crowfarn | P25: Johnson Electric Group Mexico, S. de R. L. de C.V. | Q25: Boulevard Morelos # 1109,Mega Parque Industrial Aeropuerto de Calera,98519, Calera | R25: 5 | S25: 460.8 | T25: 585.8 | U25: 0 | V25: 460.8 | W25: 460.8 | X25: 0 | Y25: 0 | Z25: 0 | AA25: 0 | AB25: 0 | AC25: 0 | AD25: 5 | AE25: 0 | AF25: 0 | AG25: 5 | AH25: 0 | AI25: 0 | AJ25: 6173284 | AK25: Closed | AL25: 2026-04-03 | AM25: JE JMX OU | AN25: 202300058589 | AO25: 02-APR-26 | AP25: 19993.05 | AQ25: USD | AR25: 1916-1010004EN | AS25: 7200 | AT25: EA | AU25: 26101200 | AV25: Motores eléctricos de corriente directa DC | AW25: H87 | AX25: Pieza | AY25: 8501101004 | AZ25: Accionados exclusivamente por corriente continua | BC25: FG-R-2198LE26 | BD25: 0 | BE25: 4918.7603 | BG25: Outbound | BH25: Land | BI25: FG-R-2181LE25 | BJ25: JOHNSON ELECTRIC NORTH AMERICA, INC. | BK25: Memphis Distribution Services 3893 Crowfarn | BL25: M01 | BM25: 1916-1010004EN | BN25: 7200 | BO25: 585.8 | BP25: =BO25/SUMIFS($BO:$BO,$BI:$BI,BI25) -> 0.10128203 | BQ25: =_xlfn.XLOOKUP(BI25,$BC:$BC,$BE:$BE)*BP25 -> 460.32683
B26: Outbound | C26: Land | D26: {=_xlfn.REGEXEXTRACT(G26,"FG-R-\d{4}LE\d{2}")} -> FG-R-2181LE25 | E26: M46 | F26: {=_xlfn.SWITCH(TRUE,T26>0,T26,Z26)} -> 122.44 | G26: FG-R-2181LE25.M01-M45 | H26: 3 BROTHERS | I26: 560602 | J26: 2026/04/03 00:00:00 | K26: 2026/04/03 00:00:00 | L26: FG-R-2181LE25.M01-M45 | M26: UL-5606473 | N26: JOHNSON ELECTRIC NORTH AMERICA, INC. | O26: Memphis Distribution Services 3893 Crowfarn | P26: Johnson Electric Group Mexico, S. de R. L. de C.V. | Q26: Boulevard Morelos # 1109,Mega Parque Industrial Aeropuerto de Calera,98519, Calera | R26: 1 | S26: 101.44 | T26: 122.44 | U26: 50 | V26: 26.44 | W26: 101.44 | X26: 0 | Y26: 0 | Z26: 0 | AA26: 0 | AB26: 0 | AC26: 0 | AD26: 1 | AE26: 0 | AF26: 0 | AG26: 1 | AH26: 0 | AI26: 0 | AJ26: 6173291 | AK26: Closed | AL26: 2026-04-03 | AM26: JE JMX OU | AN26: 202300058574 | AO26: 02-APR-26 | AP26: 1346.81 | AQ26: USD | AR26: 1651-EQH0040EN | AS26: 200 | AT26: EA | AU26: 26101100 | AV26: Motores eléctricos de corriente alterna AC | AW26: H87 | AX26: Pieza | AY26: 8501101004 | AZ26: Accionados exclusivamente por corriente continua | BC26: FG-R-2199LE26 | BD26: 0 | BE26: 4918.7603 | BG26: Outbound | BH26: Land | BI26: FG-R-2181LE25 | BJ26: JOHNSON ELECTRIC NORTH AMERICA, INC. | BK26: Memphis Distribution Services 3893 Crowfarn | BL26: M46 | BM26: 1651-EQH0040EN | BN26: 200 | BO26: 122.44 | BP26: =BO26/SUMIFS($BO:$BO,$BI:$BI,BI26) -> 0.021169293 | BQ26: =_xlfn.XLOOKUP(BI26,$BC:$BC,$BE:$BE)*BP26 -> 96.214436
... B33: Outbound | C33: Land | D33: {=_xlfn.REGEXEXTRACT(G33,"FG-R-\d{4}LE\d{2}")} -> FG-R-2184LE25 | E33: M19 | F33: {=_xlfn.SWITCH(TRUE,T33>0,T33,Z33)} -> 468.552 | G33: FG-R-2184LE25.M19 | H33: 3 BROTHERS | I33: 561367 | J33: 2026/04/03 00:00:00 | K33: 2026/04/03 00:00:00 | L33: FG-R-2184LE25.M19 | M33: UL-5609967 | N33: SAIA-BURGESS AUTOMOTIVE ACTUATORS, LLC | O33: 755 Bill Jones Drive | P33: JOHNSON ELECTRIC NORTH AMERICA | Q33: 47660 HALYARD DRIVE | R33: 1 | S33: 447.552 | T33: 468.552 | U33: 54 | V33: 420.12 | W33: 447.552 | X33: 0 | Y33: 0 | Z33: 0 | AA33: 0 | AB33: 0 | AC33: 0 | AD33: 1 | AE33: 0 | AF33: 0 | AG33: 1 | AH33: 0 | AI33: 0 | AJ33: 6173326 | AK33: Closed | AL33: 2026-04-03 | AM33: JE USA OU | AN33: 202000289783 | AO33: 02-APR-26 | AP33: 4814.88 | AQ33: USD | AR33: 1999-5YY1256EN | AS33: 216 | AT33: EA | AU33: 26101200 | AV33: Motores eléctricos de corriente directa DC | AW33: H87 | AX33: Pieza | AY33: 8501310500 | AZ33: Motores con potencia superior o igual a 186 W (¼ CP), excepto lo comprendido en las fracciones arancelarias 8501.31.03 y 8501.31.04 | BC33: FG-R-2206LE26 | BD33: 0 | BE33: 4918.7603 | BG33: Outbound | BH33: Land | BI33: FG-R-2182LE25 | BJ33: JOHNSON ELECTRIC NORTH AMERICA, INC. | BK33: APX WH 6001 GLOBAL DISTRIBUTION WAY LOUISVILLE, KY 40228 | BL33: M45 | BM33: 1999-1E30016EU | BN33: 3528 | BO33: 3091.256 | BP33: =BO33/SUMIFS($BO:$BO,$BI:$BI,BI33) -> 0.25676748 | BQ33: =_xlfn.XLOOKUP(BI33,$BC:$BC,$BE:$BE)*BP33 -> 1547.024
B34: Outbound | C34: Land | D34: {=_xlfn.REGEXEXTRACT(G34,"FG-R-\d{4}LE\d{2}")} -> FG-R-2184LE25 | E34: M19 | F34: {=_xlfn.SWITCH(TRUE,T34>0,T34,Z34)} -> 468.552 | G34: FG-R-2184LE25.M19 | H34: 3 BROTHERS | I34: 561367 | J34: 2026/04/03 00:00:00 | K34: 2026/04/03 00:00:00 | L34: FG-R-2184LE25.M19 | M34: UL-5609967 | N34: SAIA-BURGESS AUTOMOTIVE ACTUATORS, LLC | O34: 755 Bill Jones Drive | P34: JOHNSON ELECTRIC NORTH AMERICA | Q34: 47660 HALYARD DRIVE | R34: 1 | S34: 447.552 | T34: 468.552 | U34: 54 | V34: 420.12 | W34: 447.552 | X34: 0 | Y34: 0 | Z34: 0 | AA34: 0 | AB34: 0 | AC34: 0 | AD34: 1 | AE34: 0 | AF34: 0 | AG34: 1 | AH34: 0 | AI34: 0 | AJ34: 6173326 | AK34: Closed | AL34: 2026-04-03 | AM34: JE USA OU | AN34: 202000289784 | AO34: 02-APR-26 | AP34: 4150.76 | AQ34: USD | AR34: 1999-5YY1256EN | AS34: 216 | AT34: EA | AU34: 26101200 | AV34: Motores eléctricos de corriente directa DC | AW34: H87 | AX34: Pieza | AY34: 8501310500 | AZ34: Motores con potencia superior o igual a 186 W (¼ CP), excepto lo comprendido en las fracciones arancelarias 8501.31.03 y 8501.31.04 | BG34: Outbound | BH34: Land | BI34: FG-R-2182LE25 | BJ34: JOHNSON ELECTRIC NORTH AMERICA, INC. | BK34: APX WH 6001 GLOBAL DISTRIBUTION WAY LOUISVILLE, KY 40228 | BL34: M45 | BM34: 1999-1E30016EU | BN34: 3024 | BO34: 2649.648 | BP34: =BO34/SUMIFS($BO:$BO,$BI:$BI,BI34) -> 0.22008641 | BQ34: =_xlfn.XLOOKUP(BI34,$BC:$BC,$BE:$BE)*BP34 -> 1326.0206
B35: Outbound | C35: Land | D35: {=_xlfn.REGEXEXTRACT(G35,"FG-R-\d{4}LE\d{2}")} -> FG-R-2184LE25 | E35: M19 | F35: {=_xlfn.SWITCH(TRUE,T35>0,T35,Z35)} -> 3262.476 | G35: FG-R-2184LE25.M19 | H35: 3 BROTHERS | I35: 561367 | J35: 2026/04/03 00:00:00 | K35: 2026/04/03 00:00:00 | L35: FG-R-2184LE25.M19 | M35: UL-5609967 | N35: SAIA-BURGESS AUTOMOTIVE ACTUATORS, LLC | O35: 755 Bill Jones Drive | P35: JOHNSON ELECTRIC NORTH AMERICA | Q35: 47660 HALYARD DRIVE | R35: 7 | S35: 3115.476 | T35: 3262.476 | U35: 378 | V35: 2923.452 | W35: 3115.476 | X35: 0 | Y35: 0 | Z35: 0 | AA35: 0 | AB35: 0 | AC35: 0 | AD35: 7 | AE35: 0 | AF35: 0 | AG35: 7 | AH35: 0 | AI35: 0 | AJ35: 6173322 | AK35: Closed | AL35: 2026-04-03 | AM35: JE USA OU | AN35: 202000289780 | AO35: 02-APR-26 | AP35: 34829.27 | AQ35: USD | AR35: 1999-5YY2043EN | AS35: 1134 | AT35: EA | AU35: 26101200 | AV35: Motores eléctricos de corriente directa DC | AW35: H87 | AX35: Pieza | AY35: 8501320500 | AZ35: Motores de potencia igual o inferior a 3.75 kW (5 CP) | BG35: Outbound | BH35: Land | BI35: FG-R-2183LE25 | BJ35: SAIA-BURGESS AUTOMOTIVE ACTUATORS, LLC | BK35: 755 BILL JONES DRIVE | BL35: M19 | BM35: 1999-5YY0871EN | BN35: 27 | BO35: 93.92 | BP35: =BO35/SUMIFS($BO:$BO,$BI:$BI,BI35) -> 0.0019003739 | BQ35: =_xlfn.XLOOKUP(BI35,$BC:$BC,$BE:$BE)*BP35 -> 9.8762434
B36: Outbound | C36: Land | D36: {=_xlfn.REGEXEXTRACT(G36,"FG-R-\d{4}LE\d{2}")} -> FG-R-2184LE25 | E36: M19 | F36: {=_xlfn.SWITCH(TRUE,T36>0,T36,Z36)} -> 3262.476 | G36: FG-R-2184LE25.M19 | H36: 3 BROTHERS | I36: 561367 | J36: 2026/04/03 00:00:00 | K36: 2026/04/03 00:00:00 | L36: FG-R-2184LE25.M19 | M36: UL-5609967 | N36: SAIA-BURGESS AUTOMOTIVE ACTUATORS, LLC | O36: 755 Bill Jones Drive | P36: JOHNSON ELECTRIC NORTH AMERICA | Q36: 47660 HALYARD DRIVE | R36: 7 | S36: 3115.476 | T36: 3262.476 | U36: 378 | V36: 2923.452 | W36: 3115.476 | X36: 0 | Y36: 0 | Z36: 0 | AA36: 0 | AB36: 0 | AC36: 0 | AD36: 7 | AE36: 0 | AF36: 0 | AG36: 7 | AH36: 0 | AI36: 0 | AJ36: 6173322 | AK36: Closed | AL36: 2026-04-03 | AM36: JE USA OU | AN36: 202000289781 | AO36: 02-APR-26 | AP36: 26121.96 | AQ36: USD | AR36: 1999-5YY2043EN | AS36: 1134 | AT36: EA | AU36: 26101200 | AV36: Motores eléctricos de corriente directa DC | AW36: H87 | AX36: Pieza | AY36: 8501320500 | AZ36: Motores de potencia igual o inferior a 3.75 kW (5 CP) | BG36: Outbound | BH36: Land | BI36: FG-R-2183LE25 | BJ36: SAIA-BURGESS AUTOMOTIVE ACTUATORS, LLC | BK36: 755 Bill Jones Drive | BL36: M19 | BM36: 1999-5YY1445EN | BN36: 1512 | BO36: 3326.736 | BP36: =BO36/SUMIFS($BO:$BO,$BI:$BI,BI36) -> 0.067313058 | BQ36: =_xlfn.XLOOKUP(BI36,$BC:$BC,$BE:$BE)*BP36 -> 349.82596
B37: Outbound | C37: Land | D37: {=_xlfn.REGEXEXTRACT(G37,"FG-R-\d{4}LE\d{2}")} -> FG-R-2182LE25 | E37: M23 | F37: {=_xlfn.SWITCH(TRUE,T37>0,T37,Z37)} -> 879.04 | G37: FG-R-2182LE25.M46-M45 | H37: 3 BROTHERS | I37: 562325 | J37: 2026/04/03 00:00:00 | K37: 2026/04/03 00:00:00 | L37: FG-R-2182LE25.M46-M45-2 | M37: UL-5606474 | N37: JOHNSON ELECTRIC NORTH AMERICA, INC. | O37: (TDS) Transcontinental Distribution Services, Inc 14213 Transportation Ave | P37: Johnson Electric Group Mexico, S. de R. L. de C.V. | Q37: Boulevard Morelos # 1109,Mega Parque Industrial Aeropuerto de Calera,98519, Calera | R37: 4 | S37: 795.04 | T37: 879.04 | U37: 80 | V37: 696.48 | W37: 795.04 | X37: 0 | Y37: 0 | Z37: 0 | AA37: 0 | AB37: 0 | AC37: 0 | AD37: 4 | AE37: 0 | AF37: 0 | AG37: 0 | AH37: 4 | AI37: 0 | AJ37: 6173261 | AK37: Closed | AL37: 2026-04-03 | AM37: JE JMX OU | AN37: 202300058572 | AO37: 02-APR-26 | AP37: 18152.08 | AQ37: USD | AR37: 1908-1E90003RN | AS37: 480 | AT37: EA | AU37: 40151503 | AV37: Bombas centrífugas | AW37: H87 | AX37: Pieza | AY37: 8413309902 | AZ37: Para agua | BG37: Outbound | BH37: Land | BI37: FG-R-2183LE25 | BJ37: SAIA-BURGESS AUTOMOTIVE ACTUATORS, LLC | BK37: 755 Bill Jones Drive | BL37: M19 | BM37: 1999-5YY1445EN | BN37: 1512 | BO37: 3326.736 | BP37: =BO37/SUMIFS($BO:$BO,$BI:$BI,BI37) -> 0.067313058 | BQ37: =_xlfn.XLOOKUP(BI37,$BC:$BC,$BE:$BE)*BP37 -> 349.82596
B38: Outbound | C38: Land | D38: {=_xlfn.REGEXEXTRACT(G38,"FG-R-\d{4}LE\d{2}")} -> FG-R-2182LE25 | E38: M46 | F38: {=_xlfn.SWITCH(TRUE,T38>0,T38,Z38)} -> 14.618 | G38: FG-R-2182LE25.M46-M45-2 | H38: 3 BROTHERS | I38: 562325 | J38: 2026/04/03 00:00:00 | K38: 2026/04/03 00:00:00 | L38: FG-R-2182LE25.M46-M45-2 | M38: UL-5606474 | N38: JOHNSON ELECTRIC NORTH AMERICA, INC. | O38: (TDS) Transcontinental Distribution Services, Inc 14213 Transportation Ave | P38: Johnson Electric Group Mexico, S. de R. L. de C.V. | Q38: Boulevard Morelos # 1109,Mega Parque Industrial Aeropuerto de Calera,98519, Calera | R38: 0 | S38: 0 | T38: 0 | U38: 0 | V38: 0 | W38: 0 | X38: 1 | Y38: 2.618 | Z38: 14.618 | AA38: 1 | AB38: 1.5 | AC38: 2.618 | AD38: 1 | AE38: 0 | AF38: 0 | AG38: 1 | AH38: 0 | AI38: 0 | AJ38: 6173335 | AK38: Closed | AL38: 2026-04-03 | AM38: JE JMX OU | AN38: 202300058596 | AO38: 02-APR-26 | AP38: 101.17 | AQ38: USD | AR38: 1651-MYY0054EN | AS38: 10 | AT38: EA | AU38: 26101200 | AV38: Motores eléctricos de corriente directa DC | AW38: H87 | AX38: Pieza | AY38: 8501101004 | AZ38: Accionados exclusivamente por corriente continua | BG38: Outbound | BH38: Land | BI38: FG-R-2183LE25 | BJ38: SAIA-BURGESS AUTOMOTIVE ACTUATORS, LLC | BK38: 755 Bill Jones Drive | BL38: M19 | BM38: 1999-5YY1445EN | BN38: 1512 | BO38: 3326.736 | BP38: =BO38/SUMIFS($BO:$BO,$BI:$BI,BI38) -> 0.067313058 | BQ38: =_xlfn.XLOOKUP(BI38,$BC:$BC,$BE:$BE)*BP38 -> 349.82596
B39: Outbound | C39: Land | D39: {=_xlfn.REGEXEXTRACT(G39,"FG-R-\d{4}LE\d{2}")} -> FG-R-2182LE25 | E39: M46 | F39: {=_xlfn.SWITCH(TRUE,T39>0,T39,Z39)} -> 105.268 | G39: FG-R-2182LE25.M46-M45-2 | H39: 3 BROTHERS | I39: 562325 | J39: 2026/04/03 00:00:00 | K39: 2026/04/03 00:00:00 | L39: FG-R-2182LE25.M46-M45-2 | M39: UL-5606474 | N39: JOHNSON ELECTRIC NORTH AMERICA, INC. | O39: (TDS) Transcontinental Distribution Services, Inc 14213 Transportation Ave | P39: Johnson Electric Group Mexico, S. de R. L. de C.V. | Q39: Boulevard Morelos # 1109,Mega Parque Industrial Aeropuerto de Calera,98519, Calera | R39: 0 | S39: 0 | T39: 0 | U39: 0 | V39: 0 | W39: 0 | X39: 1 | Y39: 93.268 | Z39: 105.268 | AA39: 14 | AB39: 77.616 | AC39: 93.268 | AD39: 1 | AE39: 0 | AF39: 0 | AG39: 1 | AH39: 0 | AI39: 0 | AJ39: 6173334 | AK39: Closed | AL39: 2026-04-03 | AM39: JE JMX OU | AN39: 202300058594 | AO39: 02-APR-26 | AP39: 5076.34 | AQ39: USD | AR39: 1651-MYY0047EN | AS39: 504 | AT39: EA | AU39: 26101200 | AV39: Motores eléctricos de corriente directa DC | AW39: H87 | AX39: Pieza | AY39: 8501101004 | AZ39: Accionados exclusivamente por corriente continua | BG39: Outbound | BH39: Land | BI39: FG-R-2183LE25 | BJ39: SAIA-BURGESS AUTOMOTIVE ACTUATORS, LLC | BK39: 755 Bill Jones Drive | BL39: M19 | BM39: 1999-5YY2044EN | BN39: 4050 | BO39: 12591.3 | BP39: =BO39/SUMIFS($BO:$BO,$BI:$BI,BI39) -> 0.25477192 | BQ39: =_xlfn.XLOOKUP(BI39,$BC:$BC,$BE:$BE)*BP39 -> 1324.0497
B40: Outbound | C40: Land | D40: {=_xlfn.REGEXEXTRACT(G40,"FG-R-\d{4}LE\d{2}")} -> FG-R-2182LE25 | E40: M45 | F40: {=_xlfn.SWITCH(TRUE,T40>0,T40,Z40)} -> 5299.296 | G40: FG-R-2182LE25.M46-M45-2 | H40: 3 BROTHERS | I40: 562325 | J40: 2026/04/03 00:00:00 | K40: 2026/04/03 00:00:00 | L40: FG-R-2182LE25.M46-M45-2 | M40: UL-5606474 | N40: JOHNSON ELECTRIC NORTH AMERICA, INC. | O40: APX WH 6001 GLOBAL DISTRIBUTION WAY LOUISVILLE, KY 40228 | P40: Johnson Electric Group Mexico, S. de R. L. de C.V. | Q40: Boulevard Morelos # 1109,Mega Parque Industrial Aeropuerto de Calera,98519, Calera | R40: 12 | S40: 5077.296 | T40: 5299.296 | U40: 504 | V40: 4886.784 | W40: 5077.296 | X40: 0 | Y40: 0 | Z40: 0 | AA40: 0 | AB40: 0 | AC40: 0 | AD40: 12 | AE40: 0 | AF40: 0 | AG40: 12 | AH40: 0 | AI40: 0 | AJ40: 6173339 | AK40: Closed | AL40: 2026-04-03 | AM40: JE JMX OU | AN40: 202300058593 | AO40: 02-APR-26 | AP40: 36297.6 | AQ40: USD | AR40: 1999-1E30016EU | AS40: 6048 | AT40: EA | AU40: 40151500 | AV40: Bombas | AW40: H87 | AX40: Pieza | AY40: 8413709999 | AZ40: Las demás | BG40: Outbound | BH40: Land | BI40: FG-R-2183LE25 | BJ40: SAIA-BURGESS AUTOMOTIVE ACTUATORS, LLC | BK40: 755 Bill Jones Drive | BL40: M19 | BM40: 1999-5YY2044EN | BN40: 4050 | BO40: 12591.3 | BP40: =BO40/SUMIFS($BO:$BO,$BI:$BI,BI40) -> 0.25477192 | BQ40: =_xlfn.XLOOKUP(BI40,$BC:$BC,$BE:$BE)*BP40 -> 1324.0497
B41: Outbound | C41: Land | D41: {=_xlfn.REGEXEXTRACT(G41,"FG-R-\d{4}LE\d{2}")} -> FG-R-2182LE25 | E41: M45 | F41: {=_xlfn.SWITCH(TRUE,T41>0,T41,Z41)} -> 3091.256 | G41: FG-R-2182LE25.M46-M45-2 | H41: 3 BROTHERS | I41: 562325 | J41: 2026/04/03 00:00:00 | K41: 2026/04/03 00:00:00 | L41: FG-R-2182LE25.M46-M45-2 | M41: UL-5606474 | N41: JOHNSON ELECTRIC NORTH AMERICA, INC. | O41: APX WH 6001 GLOBAL DISTRIBUTION WAY LOUISVILLE, KY 40228 | P41: Johnson Electric Group Mexico, S. de R. L. de C.V. | Q41: Boulevard Morelos # 1109,Mega Parque Industrial Aeropuerto de Calera,98519, Calera | R41: 7 | S41: 2961.756 | T41: 3091.256 | U41: 294 | V41: 2850.624 | W41: 2961.756 | X41: 0 | Y41: 0 | Z41: 0 | AA41: 0 | AB41: 0 | AC41: 0 | AD41: 7 | AE41: 0 | AF41: 0 | AG41: 7 | AH41: 0 | AI41: 0 | AJ41: 6173336 | AK41: Closed | AL41: 2026-04-03 | AM41: JE JMX OU | AN41: 202300058599 | AO41: 02-APR-26 | AP41: 21173.6 | AQ41: USD | AR41: 1999-1E30016EU | AS41: 3528 | AT41: EA | AU41: 40151500 | AV41: Bombas | AW41: H87 | AX41: Pieza | AY41: 8413709999 | AZ41: Las demás | BG41: Outbound | BH41: Land | BI41: FG-R-2183LE25 | BJ41: SAIA-BURGESS AUTOMOTIVE ACTUATORS, LLC | BK41: 755 Bill Jones Drive | BL41: M19 | BM41: 1999-5YY2044EN | BN41: 4050 | BO41: 12591.3 | BP41: =BO41/SUMIFS($BO:$BO,$BI:$BI,BI41) -> 0.25477192 | BQ41: =_xlfn.XLOOKUP(BI41,$BC:$BC,$BE:$BE)*BP41 -> 1324.0497
B42: Outbound | C42: Land | D42: {=_xlfn.REGEXEXTRACT(G42,"FG-R-\d{4}LE\d{2}")} -> FG-R-2182LE25 | E42: M45 | F42: {=_xlfn.SWITCH(TRUE,T42>0,T42,Z42)} -> 2649.648 | G42: FG-R-2182LE25.M46-M45-2 | H42: 3 BROTHERS | I42: 562325 | J42: 2026/04/03 00:00:00 | K42: 2026/04/03 00:00:00 | L42: FG-R-2182LE25.M46-M45-2 | M42: UL-5606474 | N42: JOHNSON ELECTRIC NORTH AMERICA, INC. | O42: APX WH 6001 GLOBAL DISTRIBUTION WAY LOUISVILLE, KY 40228 | P42: Johnson Electric Group Mexico, S. de R. L. de C.V. | Q42: Boulevard Morelos # 1109,Mega Parque Industrial Aeropuerto de Calera,98519, Calera | R42: 6 | S42: 2538.648 | T42: 2649.648 | U42: 252 | V42: 2443.392 | W42: 2538.648 | X42: 0 | Y42: 0 | Z42: 0 | AA42: 0 | AB42: 0 | AC42: 0 | AD42: 6 | AE42: 0 | AF42: 0 | AG42: 6 | AH42: 0 | AI42: 0 | AJ42: 6173337 | AK42: Closed | AL42: 2026-04-03 | AM42: JE JMX OU | AN42: 202300058600 | AO42: 02-APR-26 | AP42: 18148.8 | AQ42: USD | AR42: 1999-1E30016EU | AS42: 3024 | AT42: EA | AU42: 40151500 | AV42: Bombas | AW42: H87 | AX42: Pieza | AY42: 8413709999 | AZ42: Las demás | BG42: Outbound | BH42: Land | BI42: FG-R-2183LE25 | BJ42: SAIA-BURGESS AUTOMOTIVE ACTUATORS, LLC | BK42: 755 Bill Jones Drive | BL42: M19 | BM42: 1999-5YY0937EN | BN42: 50 | BO42: 175.62 | BP42: =BO42/SUMIFS($BO:$BO,$BI:$BI,BI42) -> 0.0035534888 | BQ42: =_xlfn.XLOOKUP(BI42,$BC:$BC,$BE:$BE)*BP42 -> 18.467482
B43: Outbound | C43: Land | D43: {=_xlfn.REGEXEXTRACT(G43,"FG-R-\d{4}LE\d{2}")} -> FG-R-2183LE25 | E43: M19 | F43: {=_xlfn.SWITCH(TRUE,T43>0,T43,Z43)} -> 93.92 | G43: FG-R-2183LE25.M19 | H43: 3 BROTHERS | I43: H06253 | J43: 2026/04/03 00:00:00 | K43: 2026/04/03 00:00:00 | L43: FG-R-2183LE25.M19 | M43: UL-5609966 | N43: SAIA-BURGESS AUTOMOTIVE ACTUATORS, LLC | O43: 755 BILL JONES DRIVE | P43: JOHNSON ELECTRIC NORTH AMERICA | Q43: 47660 HALYARD DRIVE | R43: 0 | S43: 0 | T43: 0 | U43: 0 | V43: 0 | W43: 0 | X43: 1 | Y43: 70.92 | Z43: 93.92 | AA43: 9 | AB43: 63.18 | AC43: 70.92 | AD43: 1 | AE43: 0 | AF43: 0 | AG43: 1 | AH43: 0 | AI43: 0 | AJ43: 6173352 | AK43: Closed | AL43: 2026-04-03 | AM43: JE USA OU | AN43: 202000289795 | AO43: 02-APR-26 | AP43: 1510.35 | AQ43: USD | AR43: 1999-5YY0871EN | AS43: 27 | AT43: EA | AU43: 26101200 | AV43: Motores eléctricos de corriente directa DC | AW43: H87 | AX43: Pieza | AY43: 8501310500 | AZ43: Motores con potencia superior o igual a 186 W (¼ CP), excepto lo comprendido en las fracciones arancelarias 8501.31.03 y 8501.31.04 | BG43: Outbound | BH43: Land | BI43: FG-R-2183LE25 | BJ43: SAIA-BURGESS AUTOMOTIVE ACTUATORS, LLC | BK43: 755 Bill Jones Drive | BL43: M19 | BM43: 1999-5YY2043EN | BN43: 486 | BO43: 1398.204 | BP43: =BO43/SUMIFS($BO:$BO,$BI:$BI,BI43) -> 0.02829121 | BQ43: =_xlfn.XLOOKUP(BI43,$BC:$BC,$BE:$BE)*BP43 -> 147.02942
B44: Outbound | C44: Land | D44: {=_xlfn.REGEXEXTRACT(G44,"FG-R-\d{4}LE\d{2}")} -> FG-R-2183LE25 | E44: M19 | F44: {=_xlfn.SWITCH(TRUE,T44>0,T44,Z44)} -> 3326.736 | G44: FG-R-2183LE25.M19 | H44: 3 BROTHERS | I44: H06253 | J44: 2026/04/03 00:00:00 | K44: 2026/04/03 00:00:00 | L44: FG-R-2183LE25.M19 | M44: UL-5609966 | N44: SAIA-BURGESS AUTOMOTIVE ACTUATORS, LLC | O44: 755 Bill Jones Drive | P44: JOHNSON ELECTRIC NORTH AMERICA | Q44: 47660 HALYARD DRIVE | R44: 7 | S44: 3179.736 | T44: 3326.736 | U44: 378 | V44: 2987.712 | W44: 3179.736 | X44: 0 | Y44: 0 | Z44: 0 | AA44: 0 | AB44: 0 | AC44: 0 | AD44: 7 | AE44: 0 | AF44: 0 | AG44: 7 | AH44: 0 | AI44: 0 | AJ44: 6175284 | AK44: Closed | AL44: 2026-04-03 | AM44: JE USA OU | AN44: 202000289807 | AO44: 03-APR-26 | AP44: 1833.98 | AQ44: USD | AR44: 1999-5YY1445EN | AS44: 1512 | AT44: EA | AU44: 26101200 | AV44: Motores eléctricos de corriente directa DC | AW44: H87 | AX44: Pieza | AY44: 8501310500 | AZ44: Motores con potencia superior o igual a 186 W (¼ CP), excepto lo comprendido en las fracciones arancelarias 8501.31.03 y 8501.31.04 | BG44: Outbound | BH44: Land | BI44: FG-R-2184LE25 | BJ44: SAIA-BURGESS AUTOMOTIVE ACTUATORS, LLC | BK44: 755 Bill Jones Drive | BL44: M19 | BM44: 1999-5YY1255EN | BN44: 5184 | BO44: 11245.248 | BP44: =BO44/SUMIFS($BO:$BO,$BI:$BI,BI44) -> 0.32901014 | BQ44: =_xlfn.XLOOKUP(BI44,$BC:$BC,$BE:$BE)*BP44 -> 1618.322
B45: Outbound | C45: Land | D45: {=_xlfn.REGEXEXTRACT(G45,"FG-R-\d{4}LE\d{2}")} -> FG-R-2183LE25 | E45: M19 | F45: {=_xlfn.SWITCH(TRUE,T45>0,T45,Z45)} -> 3326.736 | G45: FG-R-2183LE25.M19 | H45: 3 BROTHERS | I45: H06253 | J45: 2026/04/03 00:00:00 | K45: 2026/04/03 00:00:00 | L45: FG-R-2183LE25.M19 | M45: UL-5609966 | N45: SAIA-BURGESS AUTOMOTIVE ACTUATORS, LLC | O45: 755 Bill Jones Drive | P45: JOHNSON ELECTRIC NORTH AMERICA | Q45: 47660 HALYARD DRIVE | R45: 7 | S45: 3179.736 | T45: 3326.736 | U45: 378 | V45: 2987.712 | W45: 3179.736 | X45: 0 | Y45: 0 | Z45: 0 | AA45: 0 | AB45: 0 | AC45: 0 | AD45: 7 | AE45: 0 | AF45: 0 | AG45: 7 | AH45: 0 | AI45: 0 | AJ45: 6175284 | AK45: Closed | AL45: 2026-04-03 | AM45: JE USA OU | AN45: 202000289808 | AO45: 03-APR-26 | AP45: 54018.95 | AQ45: USD | AR45: 1999-5YY1445EN | AS45: 1512 | AT45: EA | AU45: 26101200 | AV45: Motores eléctricos de corriente directa DC | AW45: H87 | AX45: Pieza | AY45: 8501310500 | AZ45: Motores con potencia superior o igual a 186 W (¼ CP), excepto lo comprendido en las fracciones arancelarias 8501.31.03 y 8501.31.04 | BG45: Outbound | BH45: Land | BI45: FG-R-2184LE25 | BJ45: SAIA-BURGESS AUTOMOTIVE ACTUATORS, LLC | BK45: 755 Bill Jones Drive | BL45: M19 | BM45: 1999-5YY1255EN | BN45: 5184 | BO45: 11245.248 | BP45: =BO45/SUMIFS($BO:$BO,$BI:$BI,BI45) -> 0.32901014 | BQ45: =_xlfn.XLOOKUP(BI45,$BC:$BC,$BE:$BE)*BP45 -> 1618.322
... B263: Outbound | C263: Land | D263: {=_xlfn.REGEXEXTRACT(G263,"FG-R-\d{4}LE\d{2}")} -> FG-R-2202LE26 | E263: M19 | F263: {=_xlfn.SWITCH(TRUE,T263>0,T263,Z263)} -> 3801.984 | G263: FG-R-2202LE26.M19 | H263: ALFER | I263: SNLU212425 | J263: 2026/04/27 00:00:00 | K263: 2026/04/27 00:00:00 | L263: FG-R-2202LE26.M19 | M263: UL-5610060 | N263: SAIA-BURGESS AUTOMOTIVE ACTUATORS, LLC | O263: 755 Bill Jones Drive | P263: JOHNSON ELECTRIC NORTH AMERICA | Q263: 47660 HALYARD DRIVE | R263: 8 | S263: 3633.984 | T263: 3801.984 | U263: 432 | V263: 3414.528 | W263: 3633.984 | X263: 0 | Y263: 0 | Z263: 0 | AA263: 0 | AB263: 0 | AC263: 0 | AD263: 8 | AE263: 0 | AF263: 0 | AG263: 8 | AH263: 0 | AI263: 0 | AJ263: 6217294 | AK263: Closed | AL263: 2026-04-27 | AM263: JE USA OU | AN263: 202000290646 | AO263: 27-APR-26 | AP263: 34747.92 | AQ263: USD | AR263: 1999-5YY1145EN | AS263: 1728 | AT263: EA | AU263: 26101200 | AV263: Motores eléctricos de corriente directa DC | AW263: H87 | AX263: Pieza | AY263: 8501310500 | AZ263: Motores con potencia superior o igual a 186 W (¼ CP), excepto lo comprendido en las fracciones arancelarias 8501.31.03 y 8501.31.04 | BG263: Outbound | BH263: Land | BI263: FG-R-2206LE26 | BJ263: SAIA-BURGESS AUTOMOTIVE ACTUATORS, LLC | BK263: 755 Bill Jones Drive | BL263: M19 | BM263: 1999-5YY1145EN | BN263: 1944 | BO263: 4277.232 | BP263: =BO263/SUMIFS($BO:$BO,$BI:$BI,BI263) -> 0.14494571 | BQ263: =_xlfn.XLOOKUP(BI263,$BC:$BC,$BE:$BE)*BP263 -> 712.95321
B268: ═══════════════════════════════════════════════════════════════════════════════════════
B269: 🧪 SECCIÓN W18 - PRUEBA SEMANA 18 (Exportaciones) - Costo Fijo: $1,500 USD
...

Sheet Sea
B1: {=_xlfn.SEQUENCE(1,85)} -> 1 | C1: 2 | D1: 3 | E1: 4 | F1: 5 | G1: 6 | H1: 7 | I1: 8 | J1: 9 | K1: 10 | L1: 11 | M1: 12 | N1: 13 | O1: 14 | P1: 15 | Q1: 16 | R1: 17 | S1: 18 | T1: 19 | U1: 20 | V1: 21 | W1: 22 | X1: 23 | Y1: 24 | Z1: 25 | AA1: 26 | AB1: 27 | AC1: 28 | AD1: 29 | AE1: 30 | AF1: 31 | AG1: 32 | AH1: 33 | AI1: 34 | AJ1: 35 | AK1: 36 | AL1: 37 | AM1: 38 | AN1: 39 | AO1: 40 | AP1: 41 | AQ1: 42 | AR1: 43 | AS1: 44 | AT1: 45 | AU1: 46 | AV1: 47 | AW1: 48 | AX1: 49 | AY1: 50 | AZ1: 51 | BA1: 52 | BB1: 53 | BC1: 54 | BD1: 55 | BE1: 56 | BF1: 57 | BG1: 58 | BH1: 59 | BI1: 60 | BJ1: 61 | BK1: 62 | BL1: 63 | BM1: 64 | BN1: 65 | BO1: 66 | BP1: 67 | BQ1: 68 | BR1: 69 | BS1: 70 | BT1: 71 | BU1: 72 | BV1: 73 | BW1: 74 | BX1: 75 | BY1: 76 | BZ1: 77 | CA1: 78 | CB1: 79 | CC1: 80 | CD1: 81 | CE1: 82 | CF1: 83 | CG1: 84 | CH1: 85 | CN1: {=_xlfn.TOROW(IF($B$2:$CH$2="X",_xlfn.ANCHORARRAY(B1),1/0),3)} -> 1 | CO1: 15 | CP1: 51 | CQ1: 66 | CS1: Container Cost
B2: X | P2: X | AW2: WHSU5760194 | AZ2: X | BO2: X | CN2: {=_xlfn.TOROW(IF($B$2:$CH$2="X",B5:CH5,1/0),3)} -> BU | CO2: Item Code | CP2: Container Number | CQ2: Total Gross Weight | CS2: 2500
AR3: =AR8/AQ8 -> 50000 | AS3: =AR3*0.0001 -> 5 | AZ3: PRO NUMBER/ TRACKING #
B5: BU | C5: Sales Order Number | D5: Sales Coordinator | E5: Oversea Sales Coordinator | F5: Customer Number | G5: Customer Name | H5: Customer Ship-to Address | I5: Customer Alternative Name | J5: Demand Class Code | K5: Sub Application Code | L5: Order Type | M5: Shipment Priority Code | N5: Line Number | O5: Shipment Number | P5: Item Code | Q5: Item Revision | R5: Item Category | S5: Item Description | T5: Payment Term | U5: Customer Po Number | V5: Printed Customer Part number | W5: Total Requested Quantity | X5: Ship Method Code | Y5: SO Line FOB Code(Incoterm) | Z5: Fob Code(Incoterm) | AA5: Freight Terms Code (Incoterm Named Place) | AB5: Port of Loading | AC5: Destination | AD5: Promise Date | AE5: Customer Request Date | AF5: Schedule Ship Date | AG5: Subinventory | AH5: D.O. Number/PO Doc. Number | AI5: D.O. Creation Date/Actual Shipment Date | AJ5: Actual Ship Date | AK5: Shipped Quantity | AL5: Bill to Customer Number | AM5: Invoice Number | AN5: Invoice Date | AO5: Invoice Creation Date Time | AP5: Invoice Currency Code | AQ5: Invoice Unit Selling Price | AR5: Invoice Amount in Prime | AS5: Functional Currency Code | AT5: Invoice Amount in Functional Currency | AU5: Last Update By | AV5: Forwarder | AW5: Vessel Name | AX5: ETD Date | AY5: ETA Date | AZ5: Container Number | BA5: Shipment Volume | BB5: Waybill | BC5: Motor Per Carton | BD5: Weight UOM | BE5: Carton Gross Weight | BF5: Carton NET Weight | BG5: Carton Measurement UOM | BH5: Carton Length | BI5: Carton Width | BJ5: Carton Height | BK5: Number of Carton per Pallet | BL5: Weight UOM | BM5: Pallet Gross Weight | BN5: Pallet Net Weight | BO5: Total Gross Weight | BP5: Pallet Measurement UOM | BQ5: Pallet Length | BR5: Pallet Width | BS5: Pallet Height | BT5: Number of Full Pallet | BU5: Number of Non-Full Pallet | BV5: Total number of Pallet | BW5: Number of Full Carton | BX5: Number of Non-Full Carton | BY5: Total number of Carton | BZ5: Number of Motor in Full Pallet | CA5: Number of Motor in Non-Full Pallet | CB5: Total number of Motor | CC5: Total Motor Net Weight | CD5: Pallet Code | CE5: Carton Code | CF5: HS Code | CG5: Operating Unit | CJ5: List unig cont | CN5: BU | CO5: Item Code | CP5: Container Number | CQ5: Total Gross Weight | CR5: %Pond | CS5: Cost | CU5: Bu | CV5: Amount(USD) | CW5: Count | CX5: New Amoutn
B6: M01 | C6: 1015082406 | F6: 34798 | G6: JOHNSON ELECTRIC NORTH AMERICA INC. | H6: Tax ID JEG120120DD4 BOULEVARD MORELOS NO. 1109 MEGA PARQUE INDUSTRIAL AEROPUERTO DE CALERA C.P. 98519 CALERA ZACATECAS MX | I6: XEXX010101000 | J6: JEN | K6: A99 | L6: BI-INTERNAL-SWO-IM-MX | M6: FLOW | N6: 2 | O6: 1 | P6: CPPMSF3253/7EN | Q6: C | R6: DIRECT.FERRITE MAGNET.WET MAGNET: Grade 4 & 5 | S6: MAGNET (WET) | T6: TT45ASA | U6: 50950080806 | W6: 153120 | X6: SEA | Y6: CIP | Z6: CIP | AA6: MANZANILLO | AB6: HONG KONG | AC6: MANZANILLO | AD6: 46083 | AE6: 46153 | AF6: 46090 | AG6: NOR-MXA | AH6: 6123034 | AI6: 46083 | AJ6: 46083 | AK6: 153120 | AL6: 34798 | AM6: 101513753670 | AN6: 46083 | AO6: 46083.638 | AP6: USD | AQ6: 0.03348 | AR6: 5126.46 | AS6: USD | AT6: 5126.46 | AU6: JOHN JH SHI | AV6: OOCL-SEA-GEN | AW6: XIN OU ZHOU V.077E | AX6: 46093 | AY6: 46142 | AZ6: FBIU5071920 | BA6: 40' | BB6: OOLU2038497840 | BO6: 1500 | CG6: JE IM OU | CJ6: {=_xlfn._xlws.SORT(_xlfn.UNIQUE(_xlfn._xlws.FILTER($AZ$6:$AZ$1217,$AZ$6:$AZ$1217<>"")))} -> AMFU4236030 | CN6: {=_xlfn.LET(_xlpm.list,_xlfn.ANCHORARRAY(CJ6),_xlpm.data,_xlfn.CHOOSECOLS($B$5:$CG$1217,1,15,51,66),_xlpm.out,_xlfn.DROP(_xlfn.REDUCE("",_xlfn.SEQUENCE(ROWS(_xlpm.list)),_xlfn.LAMBDA(_xlpm.a,_xlpm.b,_xlfn.VSTACK(_xlpm.a,_xlfn._xlws.FILTER(_xlpm.data,_xlfn.CHOOSECOLS(_xlpm.data,3)=INDEX(_xlpm.list,_xlpm.b),"No data")))),1),_xlpm.out)} -> Capex | CO6: CAPEX-08 | CP6: AMFU4236030 | CQ6: 0 | CR6: =IFERROR(CQ6/(SUMIFS(CQ:CQ,CP:CP,CP6)),100%) -> 1 | CS6: =CR6*$CS$2 -> 2500 | CU6: {=_xlfn._xlws.SORT(_xlfn.UNIQUE(CN6:CN1167))} -> Capex | CV6: =SUMIFS(CS:CS,CN:CN,CU6) -> 7500 | CW6: 0
B7: M01 | C7: 1015082410 | F7: 34798 | G7: JOHNSON ELECTRIC NORTH AMERICA INC. | H7: Tax ID JEG120120DD4 BOULEVARD MORELOS NO. 1109 MEGA PARQUE INDUSTRIAL AEROPUERTO DE CALERA C.P. 98519 CALERA ZACATECAS MX | I7: XEXX010101000 | J7: JEN | K7: A99 | L7: BI-INTERNAL-SWO-IM-MX | M7: FLOW | N7: 4 | O7: 1 | P7: 1318-1030030EN | Q7: A | R7: DIRECT-JMX.PLASTIC MOULDING PARTS.OTHERS | S7: O-RING | T7: TT45ASA | U7: 50950080808 | W7: 50000 | X7: SEA | Y7: CIP | Z7: CIP | AA7: MANZANILLO | AB7: HONG KONG | AC7: MANZANILLO | AD7: 46083 | AE7: 46139 | AF7: 46090 | AG7: NOR-MXA | AH7: 6123037 | AI7: 46083 | AJ7: 46083 | AK7: 50000 | AL7: 34798 | AM7: 101513753673 | AN7: 46083 | AO7: 46083.638 | AP7: USD | AQ7: 0.02018 | AR7: 1009 | AS7: USD | AT7: 1009 | AU7: JOHN JH SHI | AV7: OOCL-SEA-GEN | AW7: XIN OU ZHOU V.077E | AX7: 46093 | AY7: 46142 | AZ7: FBIU5071920 | BA7: 40' | BB7: OOLU2038497840 | BE7: 0 | BF7: 0 | BM7: 0 | BN7: 0 | BO7: 20 | CG7: JE IM OU | CJ7: CAAU7526547 | CN7: Capex | CO7: CAPEX-08 | CP7: AMFU4236030 | CQ7: 0 | CR7: =IFERROR(CQ7/(SUMIFS(CQ:CQ,CP:CP,CP7)),100%) -> 1 | CS7: =CR7*$CS$2 -> 2500 | CU7: M01 | CV7: =SUMIFS(CS:CS,CN:CN,CU7) -> 20068.385 | CW7: 1 | CX7: =CV7 -> 20068.385 | CY7: =CX7/$CX$13 -> 0.14803945
